<?xml version="1.0" ?>
<sdf version="1.10">
  <model name="homecleanerbot" canonical_link="base_link">
    <pose>0 0 0 0 0 0</pose>

    <!-- ================= BASE LINK ================= -->
    <link name="base_link">
      <pose relative_to="__model__">0.25 0 0.2 0 0 0</pose>

      <inertial>
        <mass>1.0</mass>
        <inertia>
          <ixx>0.026042</ixx>
          <ixy>0</ixy>
          <ixz>0</ixz>
          <iyy>0.087891</iyy>
          <iyz>0</iyz>
          <izz>0.109375</izz>
        </inertia>
      </inertial>

      <visual name="visual">
        <geometry>
          <box>
            <size>1.0 0.5 0.25</size>
          </box>
        </geometry>
        <material>
          <ambient>0 0 1 1</ambient>
          <diffuse>0 0 1 1</diffuse>
          <specular>0 0 1 1</specular>
        </material>
      </visual>

      <collision name="collision">
        <geometry>
          <box>
            <size>1.0 0.5 0.25</size>
          </box>
        </geometry>
      </collision>
      
    </link>
<link name="laser_link">
  <pose relative_to="base_link">0.8 0 0.3 0 0 0</pose>

  <sensor name="lidar" type="gpu_lidar">
    <topic>/scan</topic>
    <update_rate>10</update_rate>
    <ignition_frame_id>laser_link</ignition_frame_id>

    <ray>
      <scan>
        <horizontal>
          <samples>360</samples>
          <min_angle>-1.396263</min_angle>
          <max_angle>1.396263</max_angle>
        </horizontal>
      </scan>
      <range>
        <min>0.12</min>
        <max>8.0</max>
      </range>
    </ray>

    <visualize>true</visualize>
  </sensor>
</link>
    <!-- ================= LEFT WHEEL ================= -->
    <link name="left_wheel">
      <pose relative_to="base_link">-0.25 0.3 0 -1.5707 0 0</pose>
      <inertial>
        <mass>1.0</mass>
        <inertia>
          <ixx>0.010833</ixx>
          <iyy>0.010833</iyy>
          <izz>0.02</izz>
        </inertia>
      </inertial>
      <visual name="visual">
        <geometry>
          <cylinder>
            <radius>0.2</radius>
            <length>0.1</length>
          </cylinder>
        </geometry>
      </visual>
      <collision name="collision">
        <geometry>
          <cylinder>
            <radius>0.2</radius>
            <length>0.1</length>
          </cylinder>
        </geometry>
      </collision>
    </link>

    <!-- ================= RIGHT WHEEL ================= -->
    <link name="right_wheel">
      <pose relative_to="base_link">-0.25 -0.3 0 -1.5707 0 0</pose>
      <inertial>
        <mass>1.0</mass>
        <inertia>
          <ixx>0.010833</ixx>
          <iyy>0.010833</iyy>
          <izz>0.02</izz>
        </inertia>
      </inertial>
      <visual name="visual">
        <geometry>
          <cylinder>
            <radius>0.2</radius>
            <length>0.1</length>
          </cylinder>
        </geometry>
      </visual>
      <collision name="collision">
        <geometry>
          <cylinder>
            <radius>0.2</radius>
            <length>0.1</length>
          </cylinder>
        </geometry>
      </collision>
    </link>

    <!-- ================= CASTER ================= -->

    <link name="caster">
      <pose relative_to="base_link">0.4 0 -0.1 0 0 0</pose>
      <inertial>
        <mass>0.5</mass>
        <inertia>
          <ixx>0.004</ixx>
          <iyy>0.004</iyy>
          <izz>0.004</izz>
        </inertia>
      </inertial>
      <visual name="visual">
        <geometry>
          <sphere>
            <radius>0.1</radius>
          </sphere>
        </geometry>
      </visual>
      <collision name="collision">
        <geometry>
          <sphere>
            <radius>0.1</radius>
          </sphere>
        </geometry>
      </collision>
    </link>

    <!-- ================= JOINTS ================= -->
    <joint name="left_wheel_joint" type="revolute">
      <parent>base_link</parent>
      <child>left_wheel</child>
      <axis>
        <xyz expressed_in="__model__">0 1 0</xyz>
      </axis>
    </joint>

    <joint name="right_wheel_joint" type="revolute">
      <parent>base_link</parent>
      <child>right_wheel</child>
      <axis>
        <xyz expressed_in="__model__">0 1 0</xyz>
      </axis>
    </joint>

    <joint name="caster_joint" type="ball">
      <parent>base_link</parent>
      <child>caster</child>
    </joint>
<joint name="laser_joint" type="fixed">
  <parent>base_link</parent>
  <child>laser_link</child>
</joint>
    <!-- ================= DIFF DRIVE ================= -->
    <plugin
      filename="gz-sim-diff-drive-system"
      name="gz::sim::systems::DiffDrive">
      <left_joint>left_wheel_joint</left_joint>
      <right_joint>right_wheel_joint</right_joint>
      <wheel_separation>0.6</wheel_separation>
      <wheel_radius>0.2</wheel_radius>
      <odom_publish_frequency>50</odom_publish_frequency>
      <topic>cmd_vel</topic>
      <odom_topic>odom</odom_topic>
      <frame_id>odom</frame_id>
      <child_frame_id>base_link</child_frame_id>
    </plugin>

    <!-- ================= SENSORS SYSTEM ================= -->
    <plugin
      filename="gz-sim-sensors-system"
      name="gz::sim::systems::Sensors">
      <render_engine>ogre2</render_engine>
    </plugin>
  </model>
</sdf>

